{
 "cells": [
  {
   "cell_type": "markdown",
   "id": "7e31a90b-024d-4db5-85ef-ecfae7480aa3",
   "metadata": {},
   "source": [
    "# TruLens 和 LiteLLM"
   ]
  },
  {
   "cell_type": "markdown",
   "id": "796be90d-d786-4cd5-a6a0-430f7233ad46",
   "metadata": {},
   "source": [
    "无法正常生成ollama的嵌入。"
   ]
  },
  {
   "cell_type": "code",
   "execution_count": 1,
   "id": "b0d5577d-e25e-41b9-b20c-b7d8ef775884",
   "metadata": {},
   "outputs": [
    {
     "name": "stdout",
     "output_type": "stream",
     "text": [
      "CPU times: user 2 µs, sys: 0 ns, total: 2 µs\n",
      "Wall time: 3.34 µs\n"
     ]
    }
   ],
   "source": [
    "%%time\n",
    "\n",
    "university_info = \"\"\"\n",
    "The University of Washington, founded in 1861 in Seattle, is a public research university\n",
    "with over 45,000 students across three campuses in Seattle, Tacoma, and Bothell.\n",
    "As the flagship institution of the six public universities in Washington state,\n",
    "UW encompasses over 500 buildings and 20 million square feet of space,\n",
    "including one of the largest library systems in the world.\n",
    "\"\"\""
   ]
  },
  {
   "cell_type": "code",
   "execution_count": 5,
   "id": "b4aeb5d1-0177-4cac-b129-e350aab3f697",
   "metadata": {},
   "outputs": [
    {
     "name": "stdout",
     "output_type": "stream",
     "text": [
      "CPU times: user 1.17 ms, sys: 95 µs, total: 1.27 ms\n",
      "Wall time: 892 µs\n"
     ]
    }
   ],
   "source": [
    "%%time\n",
    "\n",
    "import nest_asyncio\n",
    "nest_asyncio.apply()"
   ]
  },
  {
   "cell_type": "code",
   "execution_count": 8,
   "id": "e7db9edf-e150-4ac5-9846-c7cf91eb7977",
   "metadata": {},
   "outputs": [
    {
     "name": "stderr",
     "output_type": "stream",
     "text": [
      "\u001b[92m15:01:34 - LiteLLM:WARNING\u001b[0m: utils.py:350 - `litellm.set_verbose` is deprecated. Please set `os.environ['LITELLM_LOG'] = 'DEBUG'` for debug logs.\n"
     ]
    },
    {
     "name": "stdout",
     "output_type": "stream",
     "text": [
      "\n",
      "\n",
      "\u001b[92mRequest to litellm:\u001b[0m\n",
      "\u001b[92mlitellm.embedding(model='ollama/quentinz/bge-large-zh-v1.5', api_base='http://monkey:11434/v1', input='\\nThe University of Washington, founded in 1861 in Seattle, is a public research university\\nwith over 45,000 students across three campuses in Seattle, Tacoma, and Bothell.\\nAs the flagship institution of the six public universities in Washington state,\\nUW encompasses over 500 buildings and 20 million square feet of space,\\nincluding one of the largest library systems in the world.\\n')\u001b[0m\n",
      "\n",
      "\n",
      "SYNC kwargs[caching]: False; litellm.cache: None; kwargs.get('cache')['no-cache']: False\n",
      "RAW RESPONSE:\n",
      "'EmbeddingResponse' object has no attribute 'pre_call'\n",
      "\n",
      "\n",
      "\n",
      "\u001b[1;31mGive Feedback / Get Help: https://github.com/BerriAI/litellm/issues/new\u001b[0m\n",
      "LiteLLM.Info: If you need to debug this error, use `litellm.set_verbose=True'.\n",
      "\n",
      "\n",
      "\u001b[1;31mProvider List: https://docs.litellm.ai/docs/providers\u001b[0m\n",
      "\n",
      "Logging Details: logger_fn - None | callable(logger_fn) - False\n"
     ]
    },
    {
     "ename": "APIConnectionError",
     "evalue": "litellm.APIConnectionError: 'EmbeddingResponse' object has no attribute 'pre_call'\nTraceback (most recent call last):\n  File \"/usr/local/lib/python3.10/dist-packages/litellm/main.py\", line 3547, in embedding\n    response = ollama_embeddings_fn(  # type: ignore\n  File \"/usr/local/lib/python3.10/dist-packages/litellm/llms/ollama.py\", line 602, in ollama_embeddings\n    return asyncio.run(\n  File \"/usr/local/lib/python3.10/dist-packages/nest_asyncio.py\", line 30, in run\n    return loop.run_until_complete(task)\n  File \"/usr/local/lib/python3.10/dist-packages/nest_asyncio.py\", line 98, in run_until_complete\n    return f.result()\n  File \"/usr/lib/python3.10/asyncio/futures.py\", line 201, in result\n    raise self._exception.with_traceback(self._exception_tb)\n  File \"/usr/lib/python3.10/asyncio/tasks.py\", line 232, in __step\n    result = coro.send(None)\n  File \"/usr/local/lib/python3.10/dist-packages/litellm/llms/ollama.py\", line 542, in ollama_aembeddings\n    logging_obj.pre_call(\n  File \"/usr/local/lib/python3.10/dist-packages/pydantic/main.py\", line 811, in __getattr__\n    raise AttributeError(f'{type(self).__name__!r} object has no attribute {item!r}')\nAttributeError: 'EmbeddingResponse' object has no attribute 'pre_call'\n",
     "output_type": "error",
     "traceback": [
      "\u001b[0;31m---------------------------------------------------------------------------\u001b[0m",
      "\u001b[0;31mAttributeError\u001b[0m                            Traceback (most recent call last)",
      "File \u001b[0;32m/usr/local/lib/python3.10/dist-packages/litellm/main.py:3547\u001b[0m, in \u001b[0;36membedding\u001b[0;34m(model, input, dimensions, timeout, api_base, api_version, api_key, api_type, caching, user, custom_llm_provider, litellm_call_id, litellm_logging_obj, logger_fn, **kwargs)\u001b[0m\n\u001b[1;32m   3542\u001b[0m     ollama_embeddings_fn \u001b[38;5;241m=\u001b[39m (\n\u001b[1;32m   3543\u001b[0m         ollama\u001b[38;5;241m.\u001b[39mollama_aembeddings\n\u001b[1;32m   3544\u001b[0m         \u001b[38;5;28;01mif\u001b[39;00m aembedding \u001b[38;5;129;01mis\u001b[39;00m \u001b[38;5;28;01mTrue\u001b[39;00m\n\u001b[1;32m   3545\u001b[0m         \u001b[38;5;28;01melse\u001b[39;00m ollama\u001b[38;5;241m.\u001b[39mollama_embeddings\n\u001b[1;32m   3546\u001b[0m     )\n\u001b[0;32m-> 3547\u001b[0m     response \u001b[38;5;241m=\u001b[39m \u001b[43mollama_embeddings_fn\u001b[49m\u001b[43m(\u001b[49m\u001b[43m  \u001b[49m\u001b[38;5;66;43;03m# type: ignore\u001b[39;49;00m\n\u001b[1;32m   3548\u001b[0m \u001b[43m        \u001b[49m\u001b[43mapi_base\u001b[49m\u001b[38;5;241;43m=\u001b[39;49m\u001b[43mapi_base\u001b[49m\u001b[43m,\u001b[49m\n\u001b[1;32m   3549\u001b[0m \u001b[43m        \u001b[49m\u001b[43mmodel\u001b[49m\u001b[38;5;241;43m=\u001b[39;49m\u001b[43mmodel\u001b[49m\u001b[43m,\u001b[49m\n\u001b[1;32m   3550\u001b[0m \u001b[43m        \u001b[49m\u001b[43mprompts\u001b[49m\u001b[38;5;241;43m=\u001b[39;49m\u001b[38;5;28;43minput\u001b[39;49m\u001b[43m,\u001b[49m\n\u001b[1;32m   3551\u001b[0m \u001b[43m        \u001b[49m\u001b[43mencoding\u001b[49m\u001b[38;5;241;43m=\u001b[39;49m\u001b[43mencoding\u001b[49m\u001b[43m,\u001b[49m\n\u001b[1;32m   3552\u001b[0m \u001b[43m        \u001b[49m\u001b[43mlogging_obj\u001b[49m\u001b[38;5;241;43m=\u001b[39;49m\u001b[43mlogging\u001b[49m\u001b[43m,\u001b[49m\n\u001b[1;32m   3553\u001b[0m \u001b[43m        \u001b[49m\u001b[43moptional_params\u001b[49m\u001b[38;5;241;43m=\u001b[39;49m\u001b[43moptional_params\u001b[49m\u001b[43m,\u001b[49m\n\u001b[1;32m   3554\u001b[0m \u001b[43m        \u001b[49m\u001b[43mmodel_response\u001b[49m\u001b[38;5;241;43m=\u001b[39;49m\u001b[43mEmbeddingResponse\u001b[49m\u001b[43m(\u001b[49m\u001b[43m)\u001b[49m\u001b[43m,\u001b[49m\n\u001b[1;32m   3555\u001b[0m \u001b[43m    \u001b[49m\u001b[43m)\u001b[49m\n\u001b[1;32m   3556\u001b[0m \u001b[38;5;28;01melif\u001b[39;00m custom_llm_provider \u001b[38;5;241m==\u001b[39m \u001b[38;5;124m\"\u001b[39m\u001b[38;5;124msagemaker\u001b[39m\u001b[38;5;124m\"\u001b[39m:\n",
      "File \u001b[0;32m/usr/local/lib/python3.10/dist-packages/litellm/llms/ollama.py:602\u001b[0m, in \u001b[0;36mollama_embeddings\u001b[0;34m(api_base, model, prompts, optional_params, logging_obj, model_response, encoding)\u001b[0m\n\u001b[1;32m    593\u001b[0m \u001b[38;5;28;01mdef\u001b[39;00m \u001b[38;5;21mollama_embeddings\u001b[39m(\n\u001b[1;32m    594\u001b[0m     api_base: \u001b[38;5;28mstr\u001b[39m,\n\u001b[1;32m    595\u001b[0m     model: \u001b[38;5;28mstr\u001b[39m,\n\u001b[0;32m   (...)\u001b[0m\n\u001b[1;32m    600\u001b[0m     encoding\u001b[38;5;241m=\u001b[39m\u001b[38;5;28;01mNone\u001b[39;00m,\n\u001b[1;32m    601\u001b[0m ):\n\u001b[0;32m--> 602\u001b[0m     \u001b[38;5;28;01mreturn\u001b[39;00m \u001b[43masyncio\u001b[49m\u001b[38;5;241;43m.\u001b[39;49m\u001b[43mrun\u001b[49m\u001b[43m(\u001b[49m\n\u001b[1;32m    603\u001b[0m \u001b[43m        \u001b[49m\u001b[43mollama_aembeddings\u001b[49m\u001b[43m(\u001b[49m\n\u001b[1;32m    604\u001b[0m \u001b[43m            \u001b[49m\u001b[43mapi_base\u001b[49m\u001b[43m,\u001b[49m\n\u001b[1;32m    605\u001b[0m \u001b[43m            \u001b[49m\u001b[43mmodel\u001b[49m\u001b[43m,\u001b[49m\n\u001b[1;32m    606\u001b[0m \u001b[43m            \u001b[49m\u001b[43mprompts\u001b[49m\u001b[43m,\u001b[49m\n\u001b[1;32m    607\u001b[0m \u001b[43m            \u001b[49m\u001b[43moptional_params\u001b[49m\u001b[43m,\u001b[49m\n\u001b[1;32m    608\u001b[0m \u001b[43m            \u001b[49m\u001b[43mlogging_obj\u001b[49m\u001b[43m,\u001b[49m\n\u001b[1;32m    609\u001b[0m \u001b[43m            \u001b[49m\u001b[43mmodel_response\u001b[49m\u001b[43m,\u001b[49m\n\u001b[1;32m    610\u001b[0m \u001b[43m            \u001b[49m\u001b[43mencoding\u001b[49m\u001b[43m,\u001b[49m\n\u001b[1;32m    611\u001b[0m \u001b[43m        \u001b[49m\u001b[43m)\u001b[49m\n\u001b[1;32m    612\u001b[0m \u001b[43m    \u001b[49m\u001b[43m)\u001b[49m\n",
      "File \u001b[0;32m/usr/local/lib/python3.10/dist-packages/nest_asyncio.py:30\u001b[0m, in \u001b[0;36m_patch_asyncio.<locals>.run\u001b[0;34m(main, debug)\u001b[0m\n\u001b[1;32m     29\u001b[0m \u001b[38;5;28;01mtry\u001b[39;00m:\n\u001b[0;32m---> 30\u001b[0m     \u001b[38;5;28;01mreturn\u001b[39;00m \u001b[43mloop\u001b[49m\u001b[38;5;241;43m.\u001b[39;49m\u001b[43mrun_until_complete\u001b[49m\u001b[43m(\u001b[49m\u001b[43mtask\u001b[49m\u001b[43m)\u001b[49m\n\u001b[1;32m     31\u001b[0m \u001b[38;5;28;01mfinally\u001b[39;00m:\n",
      "File \u001b[0;32m/usr/local/lib/python3.10/dist-packages/nest_asyncio.py:98\u001b[0m, in \u001b[0;36m_patch_loop.<locals>.run_until_complete\u001b[0;34m(self, future)\u001b[0m\n\u001b[1;32m     96\u001b[0m     \u001b[38;5;28;01mraise\u001b[39;00m \u001b[38;5;167;01mRuntimeError\u001b[39;00m(\n\u001b[1;32m     97\u001b[0m         \u001b[38;5;124m'\u001b[39m\u001b[38;5;124mEvent loop stopped before Future completed.\u001b[39m\u001b[38;5;124m'\u001b[39m)\n\u001b[0;32m---> 98\u001b[0m \u001b[38;5;28;01mreturn\u001b[39;00m \u001b[43mf\u001b[49m\u001b[38;5;241;43m.\u001b[39;49m\u001b[43mresult\u001b[49m\u001b[43m(\u001b[49m\u001b[43m)\u001b[49m\n",
      "File \u001b[0;32m/usr/lib/python3.10/asyncio/futures.py:201\u001b[0m, in \u001b[0;36mFuture.result\u001b[0;34m(self)\u001b[0m\n\u001b[1;32m    200\u001b[0m \u001b[38;5;28;01mif\u001b[39;00m \u001b[38;5;28mself\u001b[39m\u001b[38;5;241m.\u001b[39m_exception \u001b[38;5;129;01mis\u001b[39;00m \u001b[38;5;129;01mnot\u001b[39;00m \u001b[38;5;28;01mNone\u001b[39;00m:\n\u001b[0;32m--> 201\u001b[0m     \u001b[38;5;28;01mraise\u001b[39;00m \u001b[38;5;28mself\u001b[39m\u001b[38;5;241m.\u001b[39m_exception\u001b[38;5;241m.\u001b[39mwith_traceback(\u001b[38;5;28mself\u001b[39m\u001b[38;5;241m.\u001b[39m_exception_tb)\n\u001b[1;32m    202\u001b[0m \u001b[38;5;28;01mreturn\u001b[39;00m \u001b[38;5;28mself\u001b[39m\u001b[38;5;241m.\u001b[39m_result\n",
      "File \u001b[0;32m/usr/lib/python3.10/asyncio/tasks.py:232\u001b[0m, in \u001b[0;36mTask.__step\u001b[0;34m(***failed resolving arguments***)\u001b[0m\n\u001b[1;32m    229\u001b[0m \u001b[38;5;28;01mif\u001b[39;00m exc \u001b[38;5;129;01mis\u001b[39;00m \u001b[38;5;28;01mNone\u001b[39;00m:\n\u001b[1;32m    230\u001b[0m     \u001b[38;5;66;03m# We use the `send` method directly, because coroutines\u001b[39;00m\n\u001b[1;32m    231\u001b[0m     \u001b[38;5;66;03m# don't have `__iter__` and `__next__` methods.\u001b[39;00m\n\u001b[0;32m--> 232\u001b[0m     result \u001b[38;5;241m=\u001b[39m \u001b[43mcoro\u001b[49m\u001b[38;5;241;43m.\u001b[39;49m\u001b[43msend\u001b[49m\u001b[43m(\u001b[49m\u001b[38;5;28;43;01mNone\u001b[39;49;00m\u001b[43m)\u001b[49m\n\u001b[1;32m    233\u001b[0m \u001b[38;5;28;01melse\u001b[39;00m:\n",
      "File \u001b[0;32m/usr/local/lib/python3.10/dist-packages/litellm/llms/ollama.py:542\u001b[0m, in \u001b[0;36mollama_aembeddings\u001b[0;34m(api_base, model, prompts, model_response, optional_params, logging_obj, encoding)\u001b[0m\n\u001b[1;32m    541\u001b[0m \u001b[38;5;66;03m## LOGGING\u001b[39;00m\n\u001b[0;32m--> 542\u001b[0m \u001b[43mlogging_obj\u001b[49m\u001b[38;5;241;43m.\u001b[39;49m\u001b[43mpre_call\u001b[49m(\n\u001b[1;32m    543\u001b[0m     \u001b[38;5;28minput\u001b[39m\u001b[38;5;241m=\u001b[39m\u001b[38;5;28;01mNone\u001b[39;00m,\n\u001b[1;32m    544\u001b[0m     api_key\u001b[38;5;241m=\u001b[39m\u001b[38;5;28;01mNone\u001b[39;00m,\n\u001b[1;32m    545\u001b[0m     additional_args\u001b[38;5;241m=\u001b[39m{\n\u001b[1;32m    546\u001b[0m         \u001b[38;5;124m\"\u001b[39m\u001b[38;5;124mapi_base\u001b[39m\u001b[38;5;124m\"\u001b[39m: url,\n\u001b[1;32m    547\u001b[0m         \u001b[38;5;124m\"\u001b[39m\u001b[38;5;124mcomplete_input_dict\u001b[39m\u001b[38;5;124m\"\u001b[39m: data,\n\u001b[1;32m    548\u001b[0m         \u001b[38;5;124m\"\u001b[39m\u001b[38;5;124mheaders\u001b[39m\u001b[38;5;124m\"\u001b[39m: {},\n\u001b[1;32m    549\u001b[0m     },\n\u001b[1;32m    550\u001b[0m )\n\u001b[1;32m    552\u001b[0m response \u001b[38;5;241m=\u001b[39m \u001b[38;5;28;01mawait\u001b[39;00m session\u001b[38;5;241m.\u001b[39mpost(url, json\u001b[38;5;241m=\u001b[39mdata)\n",
      "File \u001b[0;32m/usr/local/lib/python3.10/dist-packages/pydantic/main.py:811\u001b[0m, in \u001b[0;36mBaseModel.__getattr__\u001b[0;34m(self, item)\u001b[0m\n\u001b[1;32m    809\u001b[0m \u001b[38;5;28;01melse\u001b[39;00m:\n\u001b[1;32m    810\u001b[0m     \u001b[38;5;66;03m# this is the current error\u001b[39;00m\n\u001b[0;32m--> 811\u001b[0m     \u001b[38;5;28;01mraise\u001b[39;00m \u001b[38;5;167;01mAttributeError\u001b[39;00m(\u001b[38;5;124mf\u001b[39m\u001b[38;5;124m'\u001b[39m\u001b[38;5;132;01m{\u001b[39;00m\u001b[38;5;28mtype\u001b[39m(\u001b[38;5;28mself\u001b[39m)\u001b[38;5;241m.\u001b[39m\u001b[38;5;18m__name__\u001b[39m\u001b[38;5;132;01m!r}\u001b[39;00m\u001b[38;5;124m object has no attribute \u001b[39m\u001b[38;5;132;01m{\u001b[39;00mitem\u001b[38;5;132;01m!r}\u001b[39;00m\u001b[38;5;124m'\u001b[39m)\n",
      "\u001b[0;31mAttributeError\u001b[0m: 'EmbeddingResponse' object has no attribute 'pre_call'",
      "\nDuring handling of the above exception, another exception occurred:\n",
      "\u001b[0;31mAPIConnectionError\u001b[0m                        Traceback (most recent call last)",
      "\u001b[0;32m<timed exec>\u001b[0m in \u001b[0;36m?\u001b[0;34m()\u001b[0m\n",
      "\u001b[0;32m/usr/local/lib/python3.10/dist-packages/litellm/utils.py\u001b[0m in \u001b[0;36m?\u001b[0;34m(*args, **kwargs)\u001b[0m\n\u001b[1;32m   1024\u001b[0m                     if (\n\u001b[1;32m   1025\u001b[0m                         \u001b[0mliteDebuggerClient\u001b[0m \u001b[0;32mand\u001b[0m \u001b[0mliteDebuggerClient\u001b[0m\u001b[0;34m.\u001b[0m\u001b[0mdashboard_url\u001b[0m \u001b[0;34m!=\u001b[0m \u001b[0;32mNone\u001b[0m\u001b[0;34m\u001b[0m\u001b[0;34m\u001b[0m\u001b[0m\n\u001b[1;32m   1026\u001b[0m                     ):  # make it easy to get to the debugger logs if you've initialized it\n\u001b[1;32m   1027\u001b[0m                         \u001b[0me\u001b[0m\u001b[0;34m.\u001b[0m\u001b[0mmessage\u001b[0m \u001b[0;34m+=\u001b[0m \u001b[0;34mf\"\\n Check the log in your dashboard - {liteDebuggerClient.dashboard_url}\"\u001b[0m\u001b[0;34m\u001b[0m\u001b[0;34m\u001b[0m\u001b[0m\n\u001b[0;32m-> 1028\u001b[0;31m             \u001b[0;32mraise\u001b[0m \u001b[0me\u001b[0m\u001b[0;34m\u001b[0m\u001b[0;34m\u001b[0m\u001b[0m\n\u001b[0m",
      "\u001b[0;32m/usr/local/lib/python3.10/dist-packages/litellm/utils.py\u001b[0m in \u001b[0;36m?\u001b[0;34m(*args, **kwargs)\u001b[0m\n\u001b[1;32m   1024\u001b[0m                     if (\n\u001b[1;32m   1025\u001b[0m                         \u001b[0mliteDebuggerClient\u001b[0m \u001b[0;32mand\u001b[0m \u001b[0mliteDebuggerClient\u001b[0m\u001b[0;34m.\u001b[0m\u001b[0mdashboard_url\u001b[0m \u001b[0;34m!=\u001b[0m \u001b[0;32mNone\u001b[0m\u001b[0;34m\u001b[0m\u001b[0;34m\u001b[0m\u001b[0m\n\u001b[1;32m   1026\u001b[0m                     ):  # make it easy to get to the debugger logs if you've initialized it\n\u001b[1;32m   1027\u001b[0m                         \u001b[0me\u001b[0m\u001b[0;34m.\u001b[0m\u001b[0mmessage\u001b[0m \u001b[0;34m+=\u001b[0m \u001b[0;34mf\"\\n Check the log in your dashboard - {liteDebuggerClient.dashboard_url}\"\u001b[0m\u001b[0;34m\u001b[0m\u001b[0;34m\u001b[0m\u001b[0m\n\u001b[0;32m-> 1028\u001b[0;31m             \u001b[0;32mraise\u001b[0m \u001b[0me\u001b[0m\u001b[0;34m\u001b[0m\u001b[0;34m\u001b[0m\u001b[0m\n\u001b[0m",
      "\u001b[0;32m/usr/local/lib/python3.10/dist-packages/litellm/main.py\u001b[0m in \u001b[0;36m?\u001b[0;34m(model, input, dimensions, timeout, api_base, api_version, api_key, api_type, caching, user, custom_llm_provider, litellm_call_id, litellm_logging_obj, logger_fn, **kwargs)\u001b[0m\n\u001b[1;32m   3639\u001b[0m             \u001b[0mapi_key\u001b[0m\u001b[0;34m=\u001b[0m\u001b[0mapi_key\u001b[0m\u001b[0;34m,\u001b[0m\u001b[0;34m\u001b[0m\u001b[0;34m\u001b[0m\u001b[0m\n\u001b[1;32m   3640\u001b[0m             \u001b[0moriginal_response\u001b[0m\u001b[0;34m=\u001b[0m\u001b[0mstr\u001b[0m\u001b[0;34m(\u001b[0m\u001b[0me\u001b[0m\u001b[0;34m)\u001b[0m\u001b[0;34m,\u001b[0m\u001b[0;34m\u001b[0m\u001b[0;34m\u001b[0m\u001b[0m\n\u001b[1;32m   3641\u001b[0m         )\n\u001b[1;32m   3642\u001b[0m         \u001b[0;31m## Map to OpenAI Exception\u001b[0m\u001b[0;34m\u001b[0m\u001b[0;34m\u001b[0m\u001b[0m\n\u001b[0;32m-> 3643\u001b[0;31m         raise exception_type(\n\u001b[0m\u001b[1;32m   3644\u001b[0m             \u001b[0mmodel\u001b[0m\u001b[0;34m=\u001b[0m\u001b[0mmodel\u001b[0m\u001b[0;34m,\u001b[0m\u001b[0;34m\u001b[0m\u001b[0;34m\u001b[0m\u001b[0m\n\u001b[1;32m   3645\u001b[0m             \u001b[0moriginal_exception\u001b[0m\u001b[0;34m=\u001b[0m\u001b[0me\u001b[0m\u001b[0;34m,\u001b[0m\u001b[0;34m\u001b[0m\u001b[0;34m\u001b[0m\u001b[0m\n\u001b[1;32m   3646\u001b[0m             \u001b[0mcustom_llm_provider\u001b[0m\u001b[0;34m=\u001b[0m\u001b[0mcustom_llm_provider\u001b[0m\u001b[0;34m,\u001b[0m\u001b[0;34m\u001b[0m\u001b[0;34m\u001b[0m\u001b[0m\n",
      "\u001b[0;32m/usr/local/lib/python3.10/dist-packages/litellm/utils.py\u001b[0m in \u001b[0;36m?\u001b[0;34m(model, original_exception, custom_llm_provider, completion_kwargs, extra_kwargs)\u001b[0m\n\u001b[1;32m   8068\u001b[0m         ):\n\u001b[1;32m   8069\u001b[0m             \u001b[0mthreading\u001b[0m\u001b[0;34m.\u001b[0m\u001b[0mThread\u001b[0m\u001b[0;34m(\u001b[0m\u001b[0mtarget\u001b[0m\u001b[0;34m=\u001b[0m\u001b[0mget_all_keys\u001b[0m\u001b[0;34m,\u001b[0m \u001b[0margs\u001b[0m\u001b[0;34m=\u001b[0m\u001b[0;34m(\u001b[0m\u001b[0me\u001b[0m\u001b[0;34m.\u001b[0m\u001b[0mllm_provider\u001b[0m\u001b[0;34m,\u001b[0m\u001b[0;34m)\u001b[0m\u001b[0;34m)\u001b[0m\u001b[0;34m.\u001b[0m\u001b[0mstart\u001b[0m\u001b[0;34m(\u001b[0m\u001b[0;34m)\u001b[0m\u001b[0;34m\u001b[0m\u001b[0;34m\u001b[0m\u001b[0m\n\u001b[1;32m   8070\u001b[0m         \u001b[0;31m# don't let an error with mapping interrupt the user from receiving an error from the llm api calls\u001b[0m\u001b[0;34m\u001b[0m\u001b[0;34m\u001b[0m\u001b[0m\n\u001b[1;32m   8071\u001b[0m         \u001b[0;32mif\u001b[0m \u001b[0mexception_mapping_worked\u001b[0m\u001b[0;34m:\u001b[0m\u001b[0;34m\u001b[0m\u001b[0;34m\u001b[0m\u001b[0m\n\u001b[0;32m-> 8072\u001b[0;31m             \u001b[0;32mraise\u001b[0m \u001b[0me\u001b[0m\u001b[0;34m\u001b[0m\u001b[0;34m\u001b[0m\u001b[0m\n\u001b[0m\u001b[1;32m   8073\u001b[0m         \u001b[0;32melse\u001b[0m\u001b[0;34m:\u001b[0m\u001b[0;34m\u001b[0m\u001b[0;34m\u001b[0m\u001b[0m\n\u001b[1;32m   8074\u001b[0m             \u001b[0;32mfor\u001b[0m \u001b[0merror_type\u001b[0m \u001b[0;32min\u001b[0m \u001b[0mlitellm\u001b[0m\u001b[0;34m.\u001b[0m\u001b[0mLITELLM_EXCEPTION_TYPES\u001b[0m\u001b[0;34m:\u001b[0m\u001b[0;34m\u001b[0m\u001b[0;34m\u001b[0m\u001b[0m\n\u001b[1;32m   8075\u001b[0m                 \u001b[0;32mif\u001b[0m \u001b[0misinstance\u001b[0m\u001b[0;34m(\u001b[0m\u001b[0me\u001b[0m\u001b[0;34m,\u001b[0m \u001b[0merror_type\u001b[0m\u001b[0;34m)\u001b[0m\u001b[0;34m:\u001b[0m\u001b[0;34m\u001b[0m\u001b[0;34m\u001b[0m\u001b[0m\n",
      "\u001b[0;32m/usr/local/lib/python3.10/dist-packages/litellm/utils.py\u001b[0m in \u001b[0;36m?\u001b[0;34m(model, original_exception, custom_llm_provider, completion_kwargs, extra_kwargs)\u001b[0m\n\u001b[1;32m   8068\u001b[0m         ):\n\u001b[1;32m   8069\u001b[0m             \u001b[0mthreading\u001b[0m\u001b[0;34m.\u001b[0m\u001b[0mThread\u001b[0m\u001b[0;34m(\u001b[0m\u001b[0mtarget\u001b[0m\u001b[0;34m=\u001b[0m\u001b[0mget_all_keys\u001b[0m\u001b[0;34m,\u001b[0m \u001b[0margs\u001b[0m\u001b[0;34m=\u001b[0m\u001b[0;34m(\u001b[0m\u001b[0me\u001b[0m\u001b[0;34m.\u001b[0m\u001b[0mllm_provider\u001b[0m\u001b[0;34m,\u001b[0m\u001b[0;34m)\u001b[0m\u001b[0;34m)\u001b[0m\u001b[0;34m.\u001b[0m\u001b[0mstart\u001b[0m\u001b[0;34m(\u001b[0m\u001b[0;34m)\u001b[0m\u001b[0;34m\u001b[0m\u001b[0;34m\u001b[0m\u001b[0m\n\u001b[1;32m   8070\u001b[0m         \u001b[0;31m# don't let an error with mapping interrupt the user from receiving an error from the llm api calls\u001b[0m\u001b[0;34m\u001b[0m\u001b[0;34m\u001b[0m\u001b[0m\n\u001b[1;32m   8071\u001b[0m         \u001b[0;32mif\u001b[0m \u001b[0mexception_mapping_worked\u001b[0m\u001b[0;34m:\u001b[0m\u001b[0;34m\u001b[0m\u001b[0;34m\u001b[0m\u001b[0m\n\u001b[0;32m-> 8072\u001b[0;31m             \u001b[0;32mraise\u001b[0m \u001b[0me\u001b[0m\u001b[0;34m\u001b[0m\u001b[0;34m\u001b[0m\u001b[0m\n\u001b[0m\u001b[1;32m   8073\u001b[0m         \u001b[0;32melse\u001b[0m\u001b[0;34m:\u001b[0m\u001b[0;34m\u001b[0m\u001b[0;34m\u001b[0m\u001b[0m\n\u001b[1;32m   8074\u001b[0m             \u001b[0;32mfor\u001b[0m \u001b[0merror_type\u001b[0m \u001b[0;32min\u001b[0m \u001b[0mlitellm\u001b[0m\u001b[0;34m.\u001b[0m\u001b[0mLITELLM_EXCEPTION_TYPES\u001b[0m\u001b[0;34m:\u001b[0m\u001b[0;34m\u001b[0m\u001b[0;34m\u001b[0m\u001b[0m\n\u001b[1;32m   8075\u001b[0m                 \u001b[0;32mif\u001b[0m \u001b[0misinstance\u001b[0m\u001b[0;34m(\u001b[0m\u001b[0me\u001b[0m\u001b[0;34m,\u001b[0m \u001b[0merror_type\u001b[0m\u001b[0;34m)\u001b[0m\u001b[0;34m:\u001b[0m\u001b[0;34m\u001b[0m\u001b[0;34m\u001b[0m\u001b[0m\n",
      "\u001b[0;31mAPIConnectionError\u001b[0m: litellm.APIConnectionError: 'EmbeddingResponse' object has no attribute 'pre_call'\nTraceback (most recent call last):\n  File \"/usr/local/lib/python3.10/dist-packages/litellm/main.py\", line 3547, in embedding\n    response = ollama_embeddings_fn(  # type: ignore\n  File \"/usr/local/lib/python3.10/dist-packages/litellm/llms/ollama.py\", line 602, in ollama_embeddings\n    return asyncio.run(\n  File \"/usr/local/lib/python3.10/dist-packages/nest_asyncio.py\", line 30, in run\n    return loop.run_until_complete(task)\n  File \"/usr/local/lib/python3.10/dist-packages/nest_asyncio.py\", line 98, in run_until_complete\n    return f.result()\n  File \"/usr/lib/python3.10/asyncio/futures.py\", line 201, in result\n    raise self._exception.with_traceback(self._exception_tb)\n  File \"/usr/lib/python3.10/asyncio/tasks.py\", line 232, in __step\n    result = coro.send(None)\n  File \"/usr/local/lib/python3.10/dist-packages/litellm/llms/ollama.py\", line 542, in ollama_aembeddings\n    logging_obj.pre_call(\n  File \"/usr/local/lib/python3.10/dist-packages/pydantic/main.py\", line 811, in __getattr__\n    raise AttributeError(f'{type(self).__name__!r} object has no attribute {item!r}')\nAttributeError: 'EmbeddingResponse' object has no attribute 'pre_call'\n"
     ]
    }
   ],
   "source": [
    "%%time\n",
    "\n",
    "import os\n",
    "\n",
    "from litellm import embedding\n",
    "import litellm\n",
    "\n",
    "# litellm.set_verbose=True\n",
    "os.environ['LITELLM_LOG'] = 'DEBUG'\n",
    "\n",
    "embedding_response = embedding(\n",
    "    model=\"ollama/quentinz/bge-large-zh-v1.5\",\n",
    "    api_base=\"http://monkey:11434\",\n",
    "    input=university_info,\n",
    ")"
   ]
  },
  {
   "cell_type": "code",
   "execution_count": null,
   "id": "5dc5dab3-000c-485e-90e5-3cebc3a3a5c4",
   "metadata": {},
   "outputs": [],
   "source": []
  }
 ],
 "metadata": {
  "kernelspec": {
   "display_name": "Python 3 (ipykernel)",
   "language": "python",
   "name": "python3"
  },
  "language_info": {
   "codemirror_mode": {
    "name": "ipython",
    "version": 3
   },
   "file_extension": ".py",
   "mimetype": "text/x-python",
   "name": "python",
   "nbconvert_exporter": "python",
   "pygments_lexer": "ipython3",
   "version": "3.10.12"
  }
 },
 "nbformat": 4,
 "nbformat_minor": 5
}
